--TEST--
Tests that when the SUT throws an exception containing another exception, both exceptions, and their traces, are
printed.

--ARGS--
-c test --colors=always test/CapabilitiesTest.php --filter ::testNestedException$

--FILE_EXTERNAL--
../../PHPUnit runner.php

--EXPECTF--
PHPUnit %s

Runtime: %s
Configuration: %s

100% [31;1mE[0m [31;1mScriptFUSIONTest\Pip\CapabilitiesTest::testNestedException[0m [32m(%d ms)[0m

[37;41m LogicException [0m [31mfoo[0m

[31m%s%eExceptionThrower.php:%d
%s%eCapabilitiesTest.php:%d
[0m
[31mCaused by[0m
[37;41m RuntimeException [0m [31mbar[0m

[31m%s%eExceptionThrower.php:%d
%s%eCapabilitiesTest.php:%d
[0m


Time: %s

There was 1 error:

1) ScriptFUSIONTest\Pip\CapabilitiesTest::testNestedException
LogicException: foo

%s%eExceptionThrower.php:%d
%s%eCapabilitiesTest.php:%d

Caused by
RuntimeException: bar

%s%eExceptionThrower.php:%d
%s%eCapabilitiesTest.php:%d

[37;41mERRORS![0m
[37;41mTests: 1[0m[37;41m, Assertions: 0[0m[37;41m, Errors: 1[0m[37;41m.[0m
